Workbook

Sheet Rincian (th1)
A1: RINCIAN USULAN RAB | K1: TAHUN I
A3: Judul Riset | D3: : | E3: Data-Centric AI Pipeline untuk Smart Charging Hub Solar Hybrid: Integritas Data, Hybrid Ensemble Forecasting, dan Energy Management System Adaptif
A4: Fokus/Skema | D4: : | E4: RIIM Kompetisi 2026 / Kedaulatan Energi
A5: Ketua Periset | D5: : | E5: Feddy Setio Pribadi, S.T., M.Kom.
A6: Institusi | D6: : | E6: Universitas Negeri Semarang
A7: Mitra | D7: : | E7: PT. Arunika Sains Teknologi
A8: Durasi | D8: : | E8: 2 tahun; setiap periode 12 bulan
A10: No. | D10: Komponen Biaya / Aktivitas | E10: Justifikasi / Indikator Kinerja | F10: Volume | G10: Frekuensi | H10: Harga Satuan (Rp) | I10: Satuan | J10: Jumlah | K10: LPDP | L10: Mitra | M10: HPS / Sumber
A11: I. | B11: BIAYA LANGSUNG
B12: A. | C12: BIAYA LANGSUNG PERSONIL
C13: 1 | D13: Feddy Setio Pribadi, S.T., M.Kom. | E13: Ketua periset; perancang pipeline AI, data integrity, hybrid ensemble, drift detection, CPTS | F13: 1 | G13: 4 | H13: 3600000 | I13: OB | J13: 14400000 | K13: 14400000 | L13: 0 | M13: Satuan biaya RIIM 2026
C14: 2 | D14: Bagaskoro Saputro, S.Si., M.Cs. | E14: Anggota; IoT-edge, backend, MQTT/Modbus bridge, CSMS, dashboard | F14: 1 | G14: 4 | H14: 2400000 | I14: OB | J14: 9600000 | K14: 9600000 | L14: 0 | M14: Satuan biaya RIIM 2026
C15: 3 | D15: Mario Norman Syah, S.Pd., M.Eng. | E15: Anggota; formulasi EMS, CPTS-EMS, digital twin, uji hardware | F15: 1 | G15: 4 | H15: 2400000 | I15: OB | J15: 9600000 | K15: 9600000 | L15: 0 | M15: Satuan biaya RIIM 2026
C16: 4 | D16: Adhe Lingga Dewi, S.Si., M.Si. | E16: Anggota; data quality, kalibrasi sensor, ANN, dataset curation | F16: 1 | G16: 4 | H16: 2400000 | I16: OB | J16: 9600000 | K16: 9600000 | L16: 0 | M16: Satuan biaya RIIM 2026
C17: 5 | D17: Ir. Turnad Lenggo Ginta, S.T., M.T., Ph.D. | E17: Anggota; kebijakan energi, ESG, techno-economic, hilirisasi | F17: 1 | G17: 4 | H17: 2400000 | I17: OB | J17: 9600000 | K17: 9600000 | L17: 0 | M17: Satuan biaya RIIM 2026
B18: Total BLP | J18: 52800000 | K18: 52800000 | L18: 0
B19: B. | C19: BIAYA LANGSUNG NONPERSONIL
B20: B.1 | C20: Indikator 1 | D20: Pengadaan purwarupa dan platform uji smart charging hub | E20: Pembelian komponen utama (PV, BESS, inverter), instrumentasi, dan bahan pendukung purwarupa.
B21: B.1.1 | C21: Bahan Baku Purwarupa
C22: 1 | D22: Panel surya monokristalin 370 Wp | E22: 15 pcs × 370 Wp = 5,55 kWp, untuk sumber energi utama | F22: 15 | G22: 1 | H22: 1350000 | I22: unit | J22: 20250000 | K22: 20250000 | L22: 0 | M22: Spesifikasi teknis; komponen purwarupa
C23: 2 | D23: BESS LiFePO₄ 10 kWh 48V | E23: Penyimpanan energi dengan BMS internal | F23: 1 | G23: 1 | H23: 32000000 | I23: unit | J23: 32000000 | K23: 32000000 | L23: 0 | M23: Spesifikasi teknis; komponen purwarupa
C24: 3 | D24: Hybrid inverter 5 kW on/off-grid | E24: Inverter dua arah dengan MPPT, komunikasi Modbus | F24: 1 | G24: 1 | H24: 14000000 | I24: unit | J24: 14000000 | K24: 14000000 | L24: 0 | M24: Spesifikasi teknis; komponen purwarupa
B25: B.1.2 | C25: 4 | D25: Mounting struktur atap + aksesoris | E25: Rangka panel surya, bracket, stainless steel | F25: 1 | G25: 1 | H25: 5000000 | I25: paket | J25: 5000000 | K25: 5000000 | L25: 0 | M25: Komponen purwarupa
C26: 5 | D26: Kabel PV, konektor MC4, conduit | E26: Kabel DC, AC, grounding untuk interkoneksi sistem | F26: 1 | G26: 1 | H26: 4500000 | I26: lot | J26: 4500000 | K26: 4500000 | L26: 0 | M26: Bahan purwarupa
C27: 2 | D27: Embedded edge controller | E27: Eksekusi lokal EMS, data-quality checking dan fallback | F27: 2 | G27: 1 | H27: 2500000 | I27: unit | J27: =F27*G27*H27 | K27: =J27-L27 | L27: 0 | M27: HPS vendor; aset institusi
C28: 3 | D28: Energy meter tiga fasa | E28: Metering independen daya grid dan charger | F28: 2 | G28: 1 | H28: 2000000 | I28: unit | J28: =F28*G28*H28 | K28: =J28-L28 | L28: 0 | M28: HPS vendor; aset institusi
C29: 4 | D29: DC energy meter | E29: Pengukuran aliran daya sisi DC PV/BESS | F29: 2 | G29: 1 | H29: 1500000 | I29: unit | J29: =F29*G29*H29 | K29: =J29-L29 | L29: 0 | M29: HPS vendor; aset institusi
C30: 5 | D30: Managed industrial Ethernet switch | E30: Segmentasi jaringan perangkat OT/IoT | F30: 1 | G30: 1 | H30: 2500000 | I30: unit | J30: =F30*G30*H30 | K30: =J30-L30 | L30: 0 | M30: HPS vendor; aset institusi
C31: 6 | D31: Industrial 4G router | E31: Konektivitas dan redundansi komunikasi | F31: 1 | G31: 1 | H31: 2000000 | I31: unit | J31: =F31*G31*H31 | K31: =J31-L31 | L31: 0 | M31: HPS vendor; aset institusi
C32: 7 | D32: NAS/edge storage | E32: Penyimpanan telemetri lokal dan backup | F32: 1 | G32: 1 | H32: 3000000 | I32: unit | J32: =F32*G32*H32 | K32: =J32-L32 | L32: 0 | M32: HPS vendor; aset institusi
C33: 8 | D33: Portable irradiance-temperature reference meter | E33: Referensi pengukuran sensor PV dan kalibrasi lapangan | F33: 1 | G33: 1 | H33: 1500000 | I33: unit | J33: =F33*G33*H33 | K33: =J33-L33 | L33: 0 | M33: HPS vendor; aset institusi
C34: Subtotal | J34: 75750000 | K34: 75750000 | L34: 0
B35: B.1.2 | C35: Belanja Modal Instrumentasi
C36: 1 | D36: Industrial IoT gateway | E36: Akuisisi OCPP/Modbus/MQTT, buffering, watchdog | F36: 2 | G36: 1 | H36: 1500000 | I36: unit | J36: 3000000 | K36: 3000000 | L36: 0 | M36: Aset institusi
C37: 2 | D37: Embedded edge controller | E37: Eksekusi inferensi AI, buffering, store-and-forward | F37: 1 | G37: 1 | H37: 5000000 | I37: unit | J37: 5000000 | K37: 5000000 | L37: 0 | M37: Aset institusi
C38: 3 | D38: Energy meter tiga fasa | E38: Metering daya grid, charger, beban | F38: 2 | G38: 1 | H38: 1500000 | I38: unit | J38: 3000000 | K38: 3000000 | L38: 0 | M38: Aset institusi
C39: 4 | D39: Weather station + pyranometer | E39: Sensor iradiasi, suhu, kelembaban | F39: 1 | G39: 1 | H39: 5500000 | I39: unit | J39: 5500000 | K39: 5500000 | L39: 0 | M39: Aset institusi
C40: 5 | D40: Managed switch industri + 4G router | E40: Segmentasi jaringan OT/IoT + konektivitas | F40: 1 | G40: 1 | H40: 4000000 | I40: unit | J40: 4000000 | K40: 4000000 | L40: 0 | M40: Aset institusi
C41: 6 | D41: Edge storage NAS 4TB | E41: Penyimpanan telemetri, log inferensi, backup | F41: 1 | G41: 1 | H41: 4000000 | I41: unit | J41: 4000000 | K41: 4000000 | L41: 0 | M41: Aset institusi
C42: Subtotal | D42: Contactor dan solid-state relay | E42: Switching beban dan load prioritization | F42: 8 | G42: 1 | H42: 500000 | I42: set | J42: 24500000 | K42: 24500000 | L42: 0 | M42: Komponen terintegrasi dalam purwarupa
...

Sheet Rincian (th2)
A1: RINCIAN USULAN RAB | K1: TAHUN II
A3: Judul Riset | D3: : | E3: Data-Centric AI Pipeline untuk Smart Charging Hub Solar Hybrid: Integritas Data, Hybrid Ensemble Forecasting, dan Energy Management System Adaptif
A4: Fokus/Skema | D4: : | E4: RIIM Kompetisi 2026 / Kedaulatan Energi
A5: Ketua Periset | D5: : | E5: Feddy Setio Pribadi, S.T., M.Kom.
A6: Institusi | D6: : | E6: Universitas Negeri Semarang
A7: Mitra | D7: : | E7: PT. Arunika Sains Teknologi
A8: Durasi | D8: : | E8: 2 tahun; setiap periode 12 bulan
A10: No. | D10: Komponen Biaya / Aktivitas | E10: Justifikasi / Indikator Kinerja | F10: Volume | G10: Frekuensi | H10: Harga Satuan (Rp) | I10: Satuan | J10: Jumlah | K10: LPDP | L10: Mitra | M10: HPS / Sumber
A11: I. | B11: BIAYA LANGSUNG
B12: A. | C12: BIAYA LANGSUNG PERSONIL
C13: 1 | D13: Feddy Setio Pribadi, S.T., M.Kom. | E13: Ketua periset; perancang pipeline AI, data integrity, hybrid ensemble, drift detection, CPTS | F13: 1 | G13: 4 | H13: 3600000 | I13: OB | J13: 14400000 | K13: 14400000 | L13: 0 | M13: Satuan biaya RIIM 2026
C14: 2 | D14: Bagaskoro Saputro, S.Si., M.Cs. | E14: Anggota; IoT-edge, backend, MQTT/Modbus bridge, CSMS, dashboard | F14: 1 | G14: 4 | H14: 2400000 | I14: OB | J14: 9600000 | K14: 9600000 | L14: 0 | M14: Satuan biaya RIIM 2026
C15: 3 | D15: Mario Norman Syah, S.Pd., M.Eng. | E15: Anggota; formulasi EMS, CPTS-EMS, digital twin, uji hardware | F15: 1 | G15: 4 | H15: 2400000 | I15: OB | J15: 9600000 | K15: 9600000 | L15: 0 | M15: Satuan biaya RIIM 2026
C16: 4 | D16: Adhe Lingga Dewi, S.Si., M.Si. | E16: Anggota; data quality, kalibrasi sensor, ANN, dataset curation | F16: 1 | G16: 4 | H16: 2400000 | I16: OB | J16: 9600000 | K16: 9600000 | L16: 0 | M16: Satuan biaya RIIM 2026
C17: 5 | D17: Ir. Turnad Lenggo Ginta, S.T., M.T., Ph.D. | E17: Anggota; kebijakan energi, ESG, techno-economic, hilirisasi | F17: 1 | G17: 4 | H17: 2400000 | I17: OB | J17: 9600000 | K17: 9600000 | L17: 0 | M17: Satuan biaya RIIM 2026
B18: Total BLP | J18: 52800000 | K18: 52800000 | L18: 0
B19: B. | C19: BIAYA LANGSUNG NONPERSONIL
B20: B.1 | C20: Indikator 1 | D20: Operasi pilot smart charging hub, monitoring, pemeliharaan | E20: Validasi pipeline dalam operasi nyata, monitoring multi-kondisi, pemeliharaan sistem.
B21: B.1.1 | C21: Bahan Operasional & Pemeliharaan
C22: 1 | D22: Bahan operasional pilot (12 bln) | E22: Kabel, konektor, ATK, label, dokumentasi | F22: 1 | G22: 1 | H22: 6000000 | I22: paket | J22: 6000000 | K22: 6000000 | L22: 0 | M22: Bahan habis pakai
C23: 2 | D23: Suku cadang dan spare part | E23: Fuse, MCB, relay, fan, kabel cadangan | F23: 1 | G23: 1 | H23: 8000000 | I23: paket | J23: 8000000 | K23: 8000000 | L23: 0 | M23: Bahan habis pakai
C24: 3 | D24: Sensor dan node IoT pengganti | E24: Penggantian sensor drift/rusak, node tambahan | F24: 1 | G24: 1 | H24: 5000000 | I24: paket | J24: 5000000 | K24: 5000000 | L24: 0 | M24: Bahan habis pakai
B25: B.1.2 | C25: 4 | D25: Kalibrasi sensor dan alat ukur | E25: Kalibrasi ulang sensor, meter, pyranometer | F25: 1 | G25: 1 | H25: 5000000 | I25: paket | J25: 5000000 | K25: 5000000 | L25: 0 | M25: HPS jasa kalibrasi
C26: 5 | D26: Sewa alat uji power quality & battery analyzer | E26: Pengukuran power quality, SOC/SOH, efisiensi | F26: 1 | G26: 1 | H26: 8000000 | I26: paket | J26: 8000000 | K26: 8000000 | L26: 0 | M26: HPS laboratorium
C27: 6 | D27: Preventive maintenance sistem (2×) | E27: Inspeksi, cleaning, torque check, health check | F27: 2 | G27: 1 | H27: 4000000 | I27: kali | J27: 8000000 | K27: 8000000 | L27: 0 | M27: HPS jasa teknis
C28: Subtotal | D28: Reference energy meter | E28: Validasi efisiensi dan audit energi lapangan | F28: 1 | G28: 1 | H28: 5000000 | I28: unit | J28: 40000000 | K28: 40000000 | L28: 0 | M28: HPS vendor; aset institusi
B29: B.1.2 | C29: Cloud & Infrastruktur | D29: Redundant industrial IoT gateway | E29: Failover komunikasi dan store-and-forward | F29: 1 | G29: 1 | H29: 4000000 | I29: unit | J29: =F29*G29*H29 | K29: =J29-L29 | L29: 0 | M29: HPS vendor; aset institusi
C30: 1 | D30: Cloud VPS + object storage (12 bln) | E30: Operasi backend, database, dashboard, backup | F30: 1 | G30: 1 | H30: 15000000 | I30: paket | J30: 15000000 | K30: 15000000 | L30: 0 | M30: HPS layanan cloud
C31: 2 | D31: Domain, SSL, CDN, hosting | E31: Layanan web, dashboard publik | F31: 1 | G31: 1 | H31: 4000000 | I31: paket | J31: 4000000 | K31: 4000000 | L31: 0 | M31: HPS layanan
C32: 3 | D32: MQTT broker + data streaming infra | E32: EMQX/HiveMQ, pipeline data, alerting | F32: 1 | G32: 1 | H32: 5000000 | I32: paket | J32: 5000000 | K32: 5000000 | L32: 0 | M32: HPS layanan cloud
C33: 4 | D33: Konektivitas 4G untuk gateway pilot (12 bln) | E33: Data plan untuk 2 gateway | F33: 2 | G33: 12 | H33: 150000 | I33: bulan | J33: 3600000 | K33: 3600000 | L33: 0 | M33: SBM/HP
B34: B.1.3 | C34: Subtotal | J34: 27600000 | K34: 27600000 | L34: 0
B35: Total Indikator 1 | C35: 1 | D35: DC contactor BESS | E35: Switching charge/discharge dan isolasi baterai | F35: 4 | G35: 1 | H35: 800000 | I35: unit | J35: 67600000 | K35: 67600000 | L35: 0 | M35: Komponen terintegrasi dalam purwarupa
B36: B.2 | C36: Indikator 2 | D36: Diseminasi, publikasi, KI, dan luaran akhir riset | E36: Publikasi jurnal, paten, FGD, pelaporan, dan paket replikasi. | F36: 4 | G36: 1 | H36: 500000 | I36: set | J36: =F36*G36*H36 | K36: =J36-L36 | L36: 0 | M36: Komponen terintegrasi dalam purwarupa
B37: B.2.1 | C37: Diseminasi & Publikasi | D37: DC fuse dan fuse holder | E37: Proteksi arus lebih string/rack baterai | F37: 6 | G37: 1 | H37: 300000 | I37: set | J37: =F37*G37*H37 | K37: =J37-L37 | L37: 0 | M37: Komponen terintegrasi dalam purwarupa
C38: 1 | D38: Biaya publikasi jurnal internasional Q2 | E38: OA fee publikasi hasil riset | F38: 1 | G38: 1 | H38: 12000000 | I38: paket | J38: 12000000 | K38: 12000000 | L38: 0 | M38: HPS jurnal
C39: 2 | D39: Pendaftaran paten sederhana + konsultasi KI | E39: Biaya pendaftaran dan konsultasi | F39: 1 | G39: 1 | H39: 6000000 | I39: paket | J39: 6000000 | K39: 6000000 | L39: 0 | M39: DJKI/HPS
C40: 3 | D40: FGD validasi hasil + diseminasi | E40: Penerimaan pengguna, SOP, transfer pengetahuan | F40: 1 | G40: 1 | H40: 8000000 | I40: paket | J40: 8000000 | K40: 8000000 | L40: 0 | M40: SBM/internal
C41: 4 | D41: Perjalanan monitoring & pengambilan data (6×) | E41: Monitoring pilot Sleman, troubleshooting, evaluasi | F41: 6 | G41: 1 | H41: 3000000 | I41: kali | J41: 18000000 | K41: 18000000 | L41: 0 | M41: SBM tahun berjalan
C42: 5 | D42: Seminar/konferensi nasional | E42: Presentasi hasil riset | F42: 2 | G42: 1 | H42: 5000000 | I42: kali | J42: 10000000 | K42: 10000000 | L42: 0 | M42: SBM
...

Sheet Rincian (th3)
A1: RINCIAN USULAN RAB – TAHUN III TIDAK DIUSULKAN
A3: Kegiatan diusulkan selama dua tahun. Nilai Tahun III adalah Rp0.

Sheet Rekap
A1: REKAP USULAN RAB RIIM KOMPETISI 2026
A3: Judul | C3: Pengembangan Smart Charging Hub Solar Hybrid PV–BESS–Grid Berbasis AI dan IoT-Edge dengan EMS Adaptif, Mode Islanding, dan Layanan Digital
A4: Ketua | C4: Prof. Dr. Subiyanto, S.T., M.T.
A5: Institusi | C5: Universitas Negeri Semarang
A6: Mitra | C6: PT. Arunika Sains Teknologi
A7: Tim | C7: 1 ketua + 4 anggota; honorarium 4 bulan per tahun
A10: No. | B10: Komponen | C10: Tahun I | D10: % | E10: Tahun II | F10: % | G10: Total 2 Tahun | H10: Catatan
A11: 1 | B11: Biaya Langsung Personil | C11: ='Rincian (th1)'!J18 | D11: =C11/C$14 | E11: ='Rincian (th2)'!J18 | F11: =E11/E$14 | G11: =C11+E11 | H11: Honor penuh 4 bulan untuk 1 ketua + 4 anggota
A12: 2 | B12: Biaya Langsung Nonpersonil | C12: ='Rincian (th1)'!J67 | D12: =C12/C$14 | E12: ='Rincian (th2)'!J67 | F12: =E12/E$14 | G12: =C12+E12 | H12: Barang fisik diperinci; belanja modal tetap ≤10% per tahun
A13: 3 | B13: Biaya Tidak Langsung | C13: ='Rincian (th1)'!J83 | D13: =C13/C$14 | E13: ='Rincian (th2)'!J83 | F13: =E13/E$14 | G13: =C13+E13 | H13: Khusus monitoring dan evaluasi internal
B14: TOTAL | C14: ='Rincian (th1)'!J84 | D14: 1 | E14: ='Rincian (th2)'!J84 | F14: 1 | G14: =C14+E14

Sheet Daftar Barang Dibeli
A1: DAFTAR BARANG DAN KOMPONEN FISIK YANG DIBELI
A3: No. | B3: Tahun | C3: Klasifikasi | D3: Barang/Komponen | E3: Qty | F3: Satuan | G3: Harga Satuan | H3: Total | I3: Penggunaan | J3: Pencatatan
A4: 1 | B4: Tahun I | C4: Belanja modal | D4: Industrial IoT gateway | E4: 2 | F4: unit | G4: 2000000 | H4: 4000000 | I4: Akuisisi OCPP/Modbus/MQTT, buffering dan watchdog | J4: Dicatat sebagai aset institusi
A5: 2 | B5: Tahun I | C5: Belanja modal | D5: Embedded edge controller | E5: 2 | F5: unit | G5: 2500000 | H5: 5000000 | I5: Eksekusi lokal EMS, data-quality checking dan fallback | J5: Dicatat sebagai aset institusi
A6: 3 | B6: Tahun I | C6: Belanja modal | D6: Energy meter tiga fasa | E6: 2 | F6: unit | G6: 2000000 | H6: 4000000 | I6: Metering independen daya grid dan charger | J6: Dicatat sebagai aset institusi
A7: 4 | B7: Tahun I | C7: Belanja modal | D7: DC energy meter | E7: 2 | F7: unit | G7: 1500000 | H7: 3000000 | I7: Pengukuran aliran daya sisi DC PV/BESS | J7: Dicatat sebagai aset institusi
A8: 5 | B8: Tahun I | C8: Belanja modal | D8: Managed industrial Ethernet switch | E8: 1 | F8: unit | G8: 2500000 | H8: 2500000 | I8: Segmentasi jaringan perangkat OT/IoT | J8: Dicatat sebagai aset institusi
A9: 6 | B9: Tahun I | C9: Belanja modal | D9: Industrial 4G router | E9: 1 | F9: unit | G9: 2000000 | H9: 2000000 | I9: Konektivitas dan redundansi komunikasi | J9: Dicatat sebagai aset institusi
A10: 7 | B10: Tahun I | C10: Belanja modal | D10: NAS/edge storage | E10: 1 | F10: unit | G10: 3000000 | H10: 3000000 | I10: Penyimpanan telemetri lokal dan backup | J10: Dicatat sebagai aset institusi
A11: 8 | B11: Tahun I | C11: Belanja modal | D11: Portable irradiance-temperature reference meter | E11: 1 | F11: unit | G11: 1500000 | H11: 1500000 | I11: Referensi pengukuran sensor PV dan kalibrasi lapangan | J11: Dicatat sebagai aset institusi
A12: 9 | B12: Tahun I | C12: Bahan/komponen purwarupa | D12: Set smart socket controller | E12: 8 | F12: set | G12: 600000 | H12: 4800000 | I12: ESP32/MCU, relay, CT dan konektor untuk 8 titik mikromobilitas | J12: Terintegrasi/terpakai dalam purwarupa; sesuai kebijakan institusi
A13: 10 | B13: Tahun I | C13: Bahan/komponen purwarupa | D13: Current transformer sensor | E13: 12 | F13: unit | G13: 200000 | H13: 2400000 | I13: Akuisisi arus pada charger, display dan auxiliary load | J13: Terintegrasi/terpakai dalam purwarupa; sesuai kebijakan institusi
A14: 11 | B14: Tahun I | C14: Bahan/komponen purwarupa | D14: Voltage transducer terisolasi | E14: 6 | F14: unit | G14: 250000 | H14: 1500000 | I14: Pengukuran tegangan AC/DC dengan isolasi | J14: Terintegrasi/terpakai dalam purwarupa; sesuai kebijakan institusi
A15: 12 | B15: Tahun I | C15: Bahan/komponen purwarupa | D15: Sensor temperatur multipoint | E15: 12 | F15: unit | G15: 100000 | H15: 1200000 | I15: Monitoring temperatur panel, charger dan enclosure | J15: Terintegrasi/terpakai dalam purwarupa; sesuai kebijakan institusi
... A46: 43 | B46: Tahun II | C46: Bahan/komponen purwarupa | D46: Mounting bracket dan komponen enclosure | E46: 1 | F46: lot | G46: 1000000 | H46: 1000000 | I46: Penguatan perakitan panel dan sensor | J46: Terintegrasi/terpakai dalam purwarupa; sesuai kebijakan institusi
B48: RINGKASAN
B49: Tahun | C49: Jumlah Baris Barang | D49: Belanja Modal | E49: Komponen Purwarupa
B50: Tahun I | C50: 22 | D50: 25000000 | E50: 40000000
B51: Tahun II | C51: 21 | D51: 25000000 | E51: 40000000
B52: Total | C52: 43 | D52: 50000000 | E52: 80000000

Sheet Tim Periset
A1: TIM PERISET RIIM KOMPETISI 2026
A3: Posisi | B3: Nama | C3: Institusi | D3: Kepakaran | E3: Peran
A4: Ketua | B4: Prof. Dr. Subiyanto, S.T., M.T. | C4: Universitas Negeri Semarang | D4: Intelligent control, power electronics, AI | E4: Ketua; novelty, integrasi sistem, scientific governance
A5: Anggota 1 | B5: Bagaskoro Saputro, S.Si., M.Cs. | C5: BINUS University | D5: IoT-edge, backend, cybersecurity | E5: Gateway, CSMS/CMS, dashboard, interoperabilitas, keamanan
A6: Anggota 2 | B6: Mario Norman Syah, S.Pd., M.Eng. | C6: Universitas Negeri Semarang | D6: PV–BESS, power electronics, EMS | E6: Sizing PV–BESS, integrasi perangkat daya, formulasi dan pengujian EMS
A7: Anggota 3 | B7: Adhe Lingga Dewi, S.Si., M.Si. | C7: BINUS University | D7: IoT sensor, ANN/ML, data quality | E7: Kalibrasi, forecasting, anomaly detection, pengelolaan data
A8: Anggota 4 | B8: Ir. Turnad Lenggo Ginta, S.T., M.T., Ph.D. | C8: BRIN | D8: Techno-economic, energy policy, hilirisasi | E8: Analisis biaya-emisi, ESG, kebijakan, hilirisasi

Sheet Catatan
A1: CATATAN DAN VALIDASI RAB
A3: No. | B3: Aspek | C3: Tahun I | D3: Tahun II | E3: Ketentuan/Status | F3: Catatan
A4: 1 | B4: Total pendanaan | C4: 250000000 | D4: 250000000 | E4: Pagu kerja revisi | F4: Total dua tahun Rp500.000.000
A5: 2 | B5: BLP | C5: 52800000 | D5: 52800000 | E5: Maksimum 25% | F5: 1 ketua + 4 anggota, honor 4 bulan penuh
A6: 3 | B6: BLNP | C6: 184700000 | D6: 184700000 | E6: Minimum 70% | F6: 73,88% per tahun
A7: 4 | B7: BTL | C7: 12500000 | D7: 12500000 | E7: Maksimum 5% | F7: Khusus monev internal
A8: 5 | B8: Belanja modal | C8: 25000000 | D8: 25000000 | E8: 10% per tahun | F8: 8 baris Tahun I dan 7 baris Tahun II
A9: 6 | B9: Komponen purwarupa | C9: 40000000 | D9: 40000000 | E9: BLNP | F9: 14 baris komponen fisik pada setiap tahun
A11: ASUMSI DAN VALIDASI SEBELUM SUBMIT
A12: 1 | B12: Klasifikasi belanja modal dan bahan/komponen purwarupa harus dikonfirmasi dengan kebijakan pencatatan aset institusi.
A13: 2 | B13: Charger, display, PV, BESS dan inverter tetap menggunakan perangkat mitra/in-kind/sewa; surat dukungan harus menyebutkan jenis, kapasitas dan lama penggunaan.
A14: 3 | B14: HPS wajib diperbarui dengan minimal dua quotation/vendor serta SBM/SBK tahun berjalan.
A15: 4 | B15: Tidak ada pekerjaan sipil permanen; mounting yang digunakan bersifat modular/nonpermanen dan berasal dari sewa/dukungan mitra.
A16: 5 | B16: Jumlah barang diperbanyak tanpa mengubah total pagu Rp250 juta per tahun dan komposisi BLP–BLNP–BTL.
